<?xml version="1.0" ?>
<robot name="humanoid" xmlns:xacro="http://www.ros.org/wiki/xacro">

<xacro:include filename="$(find humanoid_description)/urdf/materials.xacro" />
<xacro:include filename="$(find humanoid_description)/urdf/humanoid.trans" />
<xacro:include filename="$(find humanoid_description)/urdf/humanoid.gazebo" />
<link name="base_link">
  <inertial>
    <origin xyz="-0.012883479435964856 -0.0022883102773944906 0.3195103923670224" rpy="0 0 0"/>
    <mass value="0.49620714060674026"/>
    <inertia ixx="0.001376" iyy="0.000711" izz="0.000804" ixy="0.0" iyz="-0.0" ixz="6.9e-05"/>
  </inertial>
  <visual>
    <origin xyz="0 0 0" rpy="0 0 0"/>
    <geometry>
      <mesh filename="file://$(find humanoid_description)/meshes/base_link.stl" scale="0.001 0.001 0.001"/>
    </geometry>
    <material name="silver"/>
  </visual>
  <collision>
    <origin xyz="0 0 0" rpy="0 0 0"/>
    <geometry>
      <mesh filename="file://$(find humanoid_description)/meshes/base_link.stl" scale="0.001 0.001 0.001"/>
    </geometry>
  </collision>
</link>

<link name="L_hip_joint_1">
  <inertial>
    <origin xyz="0.02476294562748635 0.0007629287180515379 -0.03845870411401925" rpy="0 0 0"/>
    <mass value="0.043964600871803455"/>
    <inertia ixx="4.7e-05" iyy="4.3e-05" izz="2.7e-05" ixy="0.0" iyz="1e-06" ixz="-1e-06"/>
  </inertial>
  <visual>
    <origin xyz="0.03132 -0.041871 -0.280792" rpy="0 0 0"/>
    <geometry>
      <mesh filename="file://$(find humanoid_description)/meshes/L_hip_joint_1.stl" scale="0.001 0.001 0.001"/>
    </geometry>
    <material name="silver"/>
  </visual>
  <collision>
    <origin xyz="0.03132 -0.041871 -0.280792" rpy="0 0 0"/>
    <geometry>
      <mesh filename="file://$(find humanoid_description)/meshes/L_hip_joint_1.stl" scale="0.001 0.001 0.001"/>
    </geometry>
  </collision>
</link>

<link name="L_thigh_1">
  <inertial>
    <origin xyz="0.0020631851599692396 0.021610549494278094 -0.03835026650914522" rpy="0 0 0"/>
    <mass value="0.6278799138265152"/>
    <inertia ixx="0.00071" iyy="0.000648" izz="0.000122" ixy="1e-06" iyz="-0.0" ixz="0.0"/>
  </inertial>
  <visual>
    <origin xyz="0.00732 -0.017871 -0.197792" rpy="0 0 0"/>
    <geometry>
      <mesh filename="file://$(find humanoid_description)/meshes/L_thigh_1.stl" scale="0.001 0.001 0.001"/>
    </geometry>
    <material name="silver"/>
  </visual>
  <collision>
    <origin xyz="0.00732 -0.017871 -0.197792" rpy="0 0 0"/>
    <geometry>
      <mesh filename="file://$(find humanoid_description)/meshes/L_thigh_1.stl" scale="0.001 0.001 0.001"/>
    </geometry>
  </collision>
</link>

<link name="L_knee_1">
  <inertial>
    <origin xyz="0.01778979357133356 0.02573859555380659 -0.029178246058454205" rpy="0 0 0"/>
    <mass value="0.03721244648561897"/>
    <inertia ixx="3.4e-05" iyy="1.8e-05" izz="2.4e-05" ixy="0.0" iyz="0.0" ixz="4e-06"/>
  </inertial>
  <visual>
    <origin xyz="0.00732 -0.017871 -0.121009" rpy="0 0 0"/>
    <geometry>
      <mesh filename="file://$(find humanoid_description)/meshes/L_knee_1.stl" scale="0.001 0.001 0.001"/>
    </geometry>
    <material name="silver"/>
  </visual>
  <collision>
    <origin xyz="0.00732 -0.017871 -0.121009" rpy="0 0 0"/>
    <geometry>
      <mesh filename="file://$(find humanoid_description)/meshes/L_knee_1.stl" scale="0.001 0.001 0.001"/>
    </geometry>
  </collision>
</link>

<link name="L_ankle_pitch_1">
  <inertial>
    <origin xyz="-0.008957916317498007 0.020419475919971005 -0.005543744818484048" rpy="0 0 0"/>
    <mass value="0.3560292146171612"/>
    <inertia ixx="0.000105" iyy="0.00013" izz="0.000126" ixy="-0.0" iyz="-1e-05" ixz="3e-06"/>
  </inertial>
  <visual>
    <origin xyz="-0.014854 -0.017871 -0.061328" rpy="0 0 0"/>
    <geometry>
      <mesh filename="file://$(find humanoid_description)/meshes/L_ankle_pitch_1.stl" scale="0.001 0.001 0.001"/>
    </geometry>
    <material name="silver"/>
  </visual>
  <collision>
    <origin xyz="-0.014854 -0.017871 -0.061328" rpy="0 0 0"/>
    <geometry>
      <mesh filename="file://$(find humanoid_description)/meshes/L_ankle_pitch_1.stl" scale="0.001 0.001 0.001"/>
    </geometry>
  </collision>
</link>

<link name="L_ankle_roll_1">
  <inertial>
    <origin xyz="0.022510537177657726 0.009228652532095816 -0.00407575705258406" rpy="0 0 0"/>
    <mass value="0.37095119393642895"/>
    <inertia ixx="9e-05" iyy="0.000124" izz="0.000168" ixy="1e-06" iyz="0.0" ixz="3e-06"/>
  </inertial>
  <visual>
    <origin xyz="0.018537 -0.031871 -0.017141" rpy="0 0 0"/>
    <geometry>
      <mesh filename="file://$(find humanoid_description)/meshes/L_ankle_roll_1.stl" scale="0.001 0.001 0.001"/>
    </geometry>
    <material name="silver"/>
  </visual>
  <collision>
    <origin xyz="0.018537 -0.031871 -0.017141" rpy="0 0 0"/>
    <geometry>
      <mesh filename="file://$(find humanoid_description)/meshes/L_ankle_roll_1.stl" scale="0.001 0.001 0.001"/>
    </geometry>
  </collision>
</link>

<link name="R_hip_joint_1">
  <inertial>
    <origin xyz="0.024762945627578324 -0.000762795394638742 -0.03845870411416624" rpy="0 0 0"/>
    <mass value="0.1224728167143094"/>
    <inertia ixx="0.000131" iyy="0.000119" izz="7.5e-05" ixy="-0.0" iyz="-4e-06" ixz="-4e-06"/>
  </inertial>
  <visual>
    <origin xyz="0.03132 0.046412 -0.280792" rpy="0 0 0"/>
    <geometry>
      <mesh filename="file://$(find humanoid_description)/meshes/R_hip_joint_1.stl" scale="0.001 0.001 0.001"/>
    </geometry>
    <material name="silver"/>
  </visual>
  <collision>
    <origin xyz="0.03132 0.046412 -0.280792" rpy="0 0 0"/>
    <geometry>
      <mesh filename="file://$(find humanoid_description)/meshes/R_hip_joint_1.stl" scale="0.001 0.001 0.001"/>
    </geometry>
  </collision>
</link>

<link name="R_thigh_1">
  <inertial>
    <origin xyz="0.002063185159969369 -0.021610415517168198 -0.03843242882065484" rpy="0 0 0"/>
    <mass value="0.6278799138265153"/>
    <inertia ixx="0.00071" iyy="0.000648" izz="0.000122" ixy="-1e-06" iyz="-0.0" ixz="-0.0"/>
  </inertial>
  <visual>
    <origin xyz="0.00732 0.022412 -0.197792" rpy="0 0 0"/>
    <geometry>
      <mesh filename="file://$(find humanoid_description)/meshes/R_thigh_1.stl" scale="0.001 0.001 0.001"/>
    </geometry>
    <material name="silver"/>
  </visual>
  <collision>
    <origin xyz="0.00732 0.022412 -0.197792" rpy="0 0 0"/>
    <geometry>
      <mesh filename="file://$(find humanoid_description)/meshes/R_thigh_1.stl" scale="0.001 0.001 0.001"/>
    </geometry>
  </collision>
</link>

<link name="R_knee_1">
  <inertial>
    <origin xyz="0.017789793571273534 -0.02573846223038475 -0.029178246058392504" rpy="0 0 0"/>
    <mass value="0.03859068524434563"/>
    <inertia ixx="3.5e-05" iyy="1.8e-05" izz="2.5e-05" ixy="-0.0" iyz="-0.0" ixz="4e-06"/>
  </inertial>
  <visual>
    <origin xyz="0.00732 0.022412 -0.121009" rpy="0 0 0"/>
    <geometry>
      <mesh filename="file://$(find humanoid_description)/meshes/R_knee_1.stl" scale="0.001 0.001 0.001"/>
    </geometry>
    <material name="silver"/>
  </visual>
  <collision>
    <origin xyz="0.00732 0.022412 -0.121009" rpy="0 0 0"/>
    <geometry>
      <mesh filename="file://$(find humanoid_description)/meshes/R_knee_1.stl" scale="0.001 0.001 0.001"/>
    </geometry>
  </collision>
</link>

<link name="R_ankle_pitch_1">
  <inertial>
    <origin xyz="-0.008957916317495346 -0.020419342902477204 -0.005539333272074516" rpy="0 0 0"/>
    <mass value="0.35602921461716464"/>
    <inertia ixx="0.000105" iyy="0.00013" izz="0.000126" ixy="0.0" iyz="1e-05" ixz="3e-06"/>
  </inertial>
  <visual>
    <origin xyz="-0.014854 0.022412 -0.061328" rpy="0 0 0"/>
    <geometry>
      <mesh filename="file://$(find humanoid_description)/meshes/R_ankle_pitch_1.stl" scale="0.001 0.001 0.001"/>
    </geometry>
    <material name="silver"/>
  </visual>
  <collision>
    <origin xyz="-0.014854 0.022412 -0.061328" rpy="0 0 0"/>
    <geometry>
      <mesh filename="file://$(find humanoid_description)/meshes/R_ankle_pitch_1.stl" scale="0.001 0.001 0.001"/>
    </geometry>
  </collision>
</link>

<link name="R_ankle_roll_1">
  <inertial>
    <origin xyz="0.022510537177669827 -0.009228518658190743 -0.004076152987495269" rpy="0 0 0"/>
    <mass value="0.3709511939353679"/>
    <inertia ixx="9e-05" iyy="0.000124" izz="0.000168" ixy="-1e-06" iyz="-0.0" ixz="3e-06"/>
  </inertial>
  <visual>
    <origin xyz="0.018537 0.036412 -0.017141" rpy="0 0 0"/>
    <geometry>
      <mesh filename="file://$(find humanoid_description)/meshes/R_ankle_roll_1.stl" scale="0.001 0.001 0.001"/>
    </geometry>
    <material name="silver"/>
  </visual>
  <collision>
    <origin xyz="0.018537 0.036412 -0.017141" rpy="0 0 0"/>
    <geometry>
      <mesh filename="file://$(find humanoid_description)/meshes/R_ankle_roll_1.stl" scale="0.001 0.001 0.001"/>
    </geometry>
  </collision>
</link>

<link name="L_shoulder_joint_1">
  <inertial>
    <origin xyz="0.0015299174878798602 0.01478285543107169 0.007715270715101474" rpy="0 0 0"/>
    <mass value="0.021144305664436213"/>
    <inertia ixx="6e-06" iyy="1.3e-05" izz="1.4e-05" ixy="-1e-06" iyz="-2e-06" ixz="-0.0"/>
  </inertial>
  <visual>
    <origin xyz="0.017934 -0.06728 -0.365021" rpy="0 0 0"/>
    <geometry>
      <mesh filename="file://$(find humanoid_description)/meshes/L_shoulder_joint_1.stl" scale="0.001 0.001 0.001"/>
    </geometry>
    <material name="silver"/>
  </visual>
  <collision>
    <origin xyz="0.017934 -0.06728 -0.365021" rpy="0 0 0"/>
    <geometry>
      <mesh filename="file://$(find humanoid_description)/meshes/L_shoulder_joint_1.stl" scale="0.001 0.001 0.001"/>
    </geometry>
  </collision>
</link>

<link name="L_upperarm_1">
  <inertial>
    <origin xyz="0.022436519365852024 0.0017478415011937254 -0.02062009535457715" rpy="0 0 0"/>
    <mass value="0.39400171797745537"/>
    <inertia ixx="0.000293" iyy="0.000363" izz="0.000109" ixy="1e-06" iyz="-4e-06" ixz="1.7e-05"/>
  </inertial>
  <visual>
    <origin xyz="0.041934 -0.098961 -0.387195" rpy="0 0 0"/>
    <geometry>
      <mesh filename="file://$(find humanoid_description)/meshes/L_upperarm_1.stl" scale="0.001 0.001 0.001"/>
    </geometry>
    <material name="silver"/>
  </visual>
  <collision>
    <origin xyz="0.041934 -0.098961 -0.387195" rpy="0 0 0"/>
    <geometry>
      <mesh filename="file://$(find humanoid_description)/meshes/L_upperarm_1.stl" scale="0.001 0.001 0.001"/>
    </geometry>
  </collision>
</link>

<link name="L_forearm_1">
  <inertial>
    <origin xyz="0.021698764719735014 0.0024589629396612606 -0.010974756579181455" rpy="0 0 0"/>
    <mass value="0.3238214913391936"/>
    <inertia ixx="8.6e-05" iyy="0.000116" izz="6.3e-05" ixy="-0.0" iyz="7e-06" ixz="1e-06"/>
  </inertial>
  <visual>
    <origin xyz="0.041434 -0.099148 -0.292803" rpy="0 0 0"/>
    <geometry>
      <mesh filename="file://$(find humanoid_description)/meshes/L_forearm_1.stl" scale="0.001 0.001 0.001"/>
    </geometry>
    <material name="silver"/>
  </visual>
  <collision>
    <origin xyz="0.041434 -0.099148 -0.292803" rpy="0 0 0"/>
    <geometry>
      <mesh filename="file://$(find humanoid_description)/meshes/L_forearm_1.stl" scale="0.001 0.001 0.001"/>
    </geometry>
  </collision>
</link>

<link name="R_shoulder_joint_1">
  <inertial>
    <origin xyz="0.001530575565089766 -0.014783722107877845 0.007715270714952593" rpy="0 0 0"/>
    <mass value="0.021144305664436244"/>
    <inertia ixx="6e-06" iyy="1.3e-05" izz="1.4e-05" ixy="1e-06" iyz="2e-06" ixz="-0.0"/>
  </inertial>
  <visual>
    <origin xyz="0.017928 0.07182 -0.365021" rpy="0 0 0"/>
    <geometry>
      <mesh filename="file://$(find humanoid_description)/meshes/R_shoulder_joint_1.stl" scale="0.001 0.001 0.001"/>
    </geometry>
    <material name="silver"/>
  </visual>
  <collision>
    <origin xyz="0.017928 0.07182 -0.365021" rpy="0 0 0"/>
    <geometry>
      <mesh filename="file://$(find humanoid_description)/meshes/R_shoulder_joint_1.stl" scale="0.001 0.001 0.001"/>
    </geometry>
  </collision>
</link>

<link name="R_upperarm_1">
  <inertial>
    <origin xyz="0.022437177458494186 -0.0017516937321476328 -0.020620095395556093" rpy="0 0 0"/>
    <mass value="0.39400171893460806"/>
    <inertia ixx="0.000293" iyy="0.000363" izz="0.000109" ixy="-1e-06" iyz="4e-06" ixz="1.7e-05"/>
  </inertial>
  <visual>
    <origin xyz="0.041928 0.103502 -0.387195" rpy="0 0 0"/>
    <geometry>
      <mesh filename="file://$(find humanoid_description)/meshes/R_upperarm_1.stl" scale="0.001 0.001 0.001"/>
    </geometry>
    <material name="silver"/>
  </visual>
  <collision>
    <origin xyz="0.041928 0.103502 -0.387195" rpy="0 0 0"/>
    <geometry>
      <mesh filename="file://$(find humanoid_description)/meshes/R_upperarm_1.stl" scale="0.001 0.001 0.001"/>
    </geometry>
  </collision>
</link>

<link name="R_forearm_1">
  <inertial>
    <origin xyz="0.02169942279604719 -0.0024636789234836892 -0.010974756579181955" rpy="0 0 0"/>
    <mass value="0.32382149133918564"/>
    <inertia ixx="8.6e-05" iyy="0.000116" izz="6.3e-05" ixy="0.0" iyz="-7e-06" ixz="1e-06"/>
  </inertial>
  <visual>
    <origin xyz="0.041428 0.103689 -0.292803" rpy="0 0 0"/>
    <geometry>
      <mesh filename="file://$(find humanoid_description)/meshes/R_forearm_1.stl" scale="0.001 0.001 0.001"/>
    </geometry>
    <material name="silver"/>
  </visual>
  <collision>
    <origin xyz="0.041428 0.103689 -0.292803" rpy="0 0 0"/>
    <geometry>
      <mesh filename="file://$(find humanoid_description)/meshes/R_forearm_1.stl" scale="0.001 0.001 0.001"/>
    </geometry>
  </collision>
</link>

<link name="Head_1">
  <inertial>
    <origin xyz="0.009916301072321384 2.611393220511727e-06 0.02595144565080304" rpy="0 0 0"/>
    <mass value="0.2579403843929263"/>
    <inertia ixx="4.3e-05" iyy="7.1e-05" izz="4.4e-05" ixy="-0.0" iyz="0.0" ixz="-1e-06"/>
  </inertial>
  <visual>
    <origin xyz="0.01732 0.00227 -0.381979" rpy="0 0 0"/>
    <geometry>
      <mesh filename="file://$(find humanoid_description)/meshes/Head_1.stl" scale="0.001 0.001 0.001"/>
    </geometry>
    <material name="silver"/>
  </visual>
  <collision>
    <origin xyz="0.01732 0.00227 -0.381979" rpy="0 0 0"/>
    <geometry>
      <mesh filename="file://$(find humanoid_description)/meshes/Head_1.stl" scale="0.001 0.001 0.001"/>
    </geometry>
  </collision>
</link>

<joint name="L_hip_joint" type="revolute">
  <origin xyz="-0.03132 0.041871 0.280792" rpy="0 0 0"/>
  <parent link="base_link"/>
  <child link="L_hip_joint_1"/>
  <axis xyz="-1.0 -0.0 -0.0"/>
  <limit upper="0.523599" lower="-1.570796" effort="100" velocity="100"/>
</joint>

<joint name="L_thigh" type="revolute">
  <origin xyz="0.024 -0.024 -0.083" rpy="0 0 0"/>
  <parent link="L_hip_joint_1"/>
  <child link="L_thigh_1"/>
  <axis xyz="0.0 -1.0 -0.0"/>
  <limit upper="2.356194" lower="-2.356194" effort="100" velocity="100"/>
</joint>

<joint name="L_knee" type="revolute">
  <origin xyz="0.0 0.0 -0.076783" rpy="0 0 0"/>
  <parent link="L_thigh_1"/>
  <child link="L_knee_1"/>
  <axis xyz="0.0 -1.0 -0.0"/>
  <limit upper="1.570796" lower="-2.356194" effort="100" velocity="100"/>
</joint>

<joint name="L_ankle_pitch" type="revolute">
  <origin xyz="0.022174 0.0 -0.059681" rpy="0 0 0"/>
  <parent link="L_knee_1"/>
  <child link="L_ankle_pitch_1"/>
  <axis xyz="-0.0 -1.0 0.0"/>
  <limit upper="1.570796" lower="-0.698132" effort="100" velocity="100"/>
</joint>

<joint name="L_ankle_roll" type="revolute">
  <origin xyz="-0.033391 0.014 -0.044187" rpy="0 0 0"/>
  <parent link="L_ankle_pitch_1"/>
  <child link="L_ankle_roll_1"/>
  <axis xyz="-1.0 -0.0 -0.0"/>
  <limit upper="1.570796" lower="-0.523599" effort="100" velocity="100"/>
</joint>

<joint name="R_hip_joint" type="revolute">
  <origin xyz="-0.03132 -0.046412 0.280792" rpy="0 0 0"/>
  <parent link="base_link"/>
  <child link="R_hip_joint_1"/>
  <axis xyz="-1.0 -0.0 -0.0"/>
  <limit upper="1.570796" lower="-0.523599" effort="100" velocity="100"/>
</joint>

<joint name="R_thigh" type="revolute">
  <origin xyz="0.024 0.024 -0.083" rpy="0 0 0"/>
  <parent link="R_hip_joint_1"/>
  <child link="R_thigh_1"/>
  <axis xyz="-0.0 1.0 0.0"/>
  <limit upper="2.356194" lower="-2.356194" effort="100" velocity="100"/>
</joint>

<joint name="R_knee" type="revolute">
  <origin xyz="0.0 0.0 -0.076783" rpy="0 0 0"/>
  <parent link="R_thigh_1"/>
  <child link="R_knee_1"/>
  <axis xyz="0.0 1.0 0.0"/>
  <limit upper="2.356194" lower="-1.570796" effort="100" velocity="100"/>
</joint>

<joint name="R_ankle_pitch" type="revolute">
  <origin xyz="0.022174 0.0 -0.059681" rpy="0 0 0"/>
  <parent link="R_knee_1"/>
  <child link="R_ankle_pitch_1"/>
  <axis xyz="-0.0 1.0 0.0"/>
  <limit upper="0.698132" lower="-1.570796" effort="100" velocity="100"/>
</joint>

<joint name="R_ankle_roll" type="revolute">
  <origin xyz="-0.033391 -0.014 -0.044187" rpy="0 0 0"/>
  <parent link="R_ankle_pitch_1"/>
  <child link="R_ankle_roll_1"/>
  <axis xyz="-1.0 -0.0 -0.0"/>
  <limit upper="0.523599" lower="-1.570796" effort="100" velocity="100"/>
</joint>

<joint name="L_shoulder_joint" type="revolute">
  <origin xyz="-0.017934 0.06728 0.365021" rpy="0 0 0"/>
  <parent link="base_link"/>
  <child link="L_shoulder_joint_1"/>
  <axis xyz="-0.0 1.0 0.0"/>
  <limit upper="3.141593" lower="-3.141593" effort="100" velocity="100"/>
</joint>

<joint name="L_upperarm" type="revolute">
  <origin xyz="-0.024 0.031681 0.022174" rpy="0 0 0"/>
  <parent link="L_shoulder_joint_1"/>
  <child link="L_upperarm_1"/>
  <axis xyz="-1.0 -0.0 0.0"/>
  <limit upper="0.174533" lower="-3.752458" effort="100" velocity="100"/>
</joint>

<joint name="L_forearm" type="revolute">
  <origin xyz="0.0005 0.000187 -0.094392" rpy="0 0 0"/>
  <parent link="L_upperarm_1"/>
  <child link="L_forearm_1"/>
  <axis xyz="-1.0 0.0 0.0"/>
  <limit upper="3.141593" lower="-2.443461" effort="100" velocity="100"/>
</joint>

<joint name="R_shoulder_joint" type="revolute">
  <origin xyz="-0.017928 -0.07182 0.365021" rpy="0 0 0"/>
  <parent link="base_link"/>
  <child link="R_shoulder_joint_1"/>
  <axis xyz="0.0 -1.0 0.0"/>
  <limit upper="3.141593" lower="-3.141593" effort="100" velocity="100"/>
</joint>

<joint name="R_upperarm" type="revolute">
  <origin xyz="-0.024 -0.031682 0.022174" rpy="0 0 0"/>
  <parent link="R_shoulder_joint_1"/>
  <child link="R_upperarm_1"/>
  <axis xyz="-1.0 -0.0 -0.0"/>
  <limit upper="3.752458" lower="-0.174533" effort="100" velocity="100"/>
</joint>

<joint name="R_forearm" type="revolute">
  <origin xyz="0.0005 -0.000187 -0.094392" rpy="0 0 0"/>
  <parent link="R_upperarm_1"/>
  <child link="R_forearm_1"/>
  <axis xyz="-1.0 0.0 -0.0"/>
  <limit upper="2.443461" lower="-3.141593" effort="100" velocity="100"/>
</joint>

<joint name="Head" type="revolute">
  <origin xyz="-0.01732 -0.00227 0.381979" rpy="0 0 0"/>
  <parent link="base_link"/>
  <child link="Head_1"/>
  <axis xyz="0.0 -0.0 1.0"/>
  <limit upper="2.356194" lower="-2.356194" effort="100" velocity="100"/>
</joint>

</robot>
